2023-07-12 07:24:08 +0000 - dagster - DEBUG - my_job - 8b97c882-a0c8-45d5-a116-67ece1a8c33b - 650 - LOGS_CAPTURED - Started capturing logs in process (pid: 650).
2023-07-12 07:24:08 +0000 - dagster - DEBUG - my_job - 8b97c882-a0c8-45d5-a116-67ece1a8c33b - 650 - a - STEP_START - Started execution of step "a".
2023-07-12 07:24:08 +0000 - dagster - ERROR - my_job - 8b97c882-a0c8-45d5-a116-67ece1a8c33b - 650 - a - STEP_FAILURE - Execution of step "a" failed.

dagster._core.errors.DagsterExecutionStepExecutionError: Error occurred while executing op "a"::

FileNotFoundError: [Errno 2] No such file or directory: '/opt/dagster/app/hello_world.sh'

Stack Trace:
  File "/usr/local/lib/python3.7/site-packages/dagster/_core/execution/plan/utils.py", line 54, in op_execution_error_boundary
    yield
  File "/usr/local/lib/python3.7/site-packages/dagster/_utils/__init__.py", line 445, in iterate_with_context
    next_output = next(iterator)
  File "/usr/local/lib/python3.7/site-packages/dagster/_core/execution/plan/compute_generator.py", line 125, in _coerce_op_compute_fn_to_iterator
    fn, context, kwargs, context_arg_provided, config_arg_class, resource_arg_mapping
  File "/usr/local/lib/python3.7/site-packages/dagster/_core/execution/plan/compute_generator.py", line 118, in invoke_compute_fn
    return fn(context, **args_to_pass) if context_arg_provided else fn(**args_to_pass)
  File "/usr/local/lib/python3.7/site-packages/dagster_shell/ops.py", line 180, in _shell_script_fn
    shell_script_path=shell_script_path, log=context.log, **config.to_execute_params()
  File "/usr/local/lib/python3.7/site-packages/dagster_shell/utils.py", line 75, in execute_script_file
    with open(shell_script_path, "rb") as f:

