2023-07-12 10:01:58 +0000 - dagster - DEBUG - example_job - 9603df70-9bc9-4bfa-b720-f0d8b5276af3 - 140441 - LOGS_CAPTURED - Started capturing logs in process (pid: 140441).
2023-07-12 10:01:58 +0000 - dagster - DEBUG - example_job - 9603df70-9bc9-4bfa-b720-f0d8b5276af3 - 140441 - create_temp_folders - STEP_START - Started execution of step "create_temp_folders".
Creating folders
2023-07-12 10:01:58 +0000 - dagster - ERROR - example_job - 9603df70-9bc9-4bfa-b720-f0d8b5276af3 - 140441 - create_temp_folders - STEP_FAILURE - Execution of step "create_temp_folders" failed.

dagster._core.errors.DagsterExecutionStepExecutionError: Error occurred while executing op "create_temp_folders"::

TypeError: create_shell_command_op() got an unexpected keyword argument 'output_logging'

Stack Trace:
  File "/usr/local/lib/python3.7/site-packages/dagster/_core/execution/plan/utils.py", line 54, in op_execution_error_boundary
    yield
  File "/usr/local/lib/python3.7/site-packages/dagster/_utils/__init__.py", line 445, in iterate_with_context
    next_output = next(iterator)
  File "/usr/local/lib/python3.7/site-packages/dagster/_core/execution/plan/compute_generator.py", line 125, in _coerce_op_compute_fn_to_iterator
    fn, context, kwargs, context_arg_provided, config_arg_class, resource_arg_mapping
  File "/usr/local/lib/python3.7/site-packages/dagster/_core/execution/plan/compute_generator.py", line 118, in invoke_compute_fn
    return fn(context, **args_to_pass) if context_arg_provided else fn(**args_to_pass)
  File "/opt/dagster/app/s3.py", line 38, in create_temp_folders
    create_shell_command_op('mkdir -p /tmp/data/raw && mkdir -p /tmp/data/processed && mkdir -p /tmp/scripts/etl', output_logging="STREAM", log=context.log, name="create_folders")

